

2021-07-28 15:33:13,747 
Ashirvad.Logger.EventLogger                         [(null)] 
>> System.Data.Entity.Core.EntityException: The underlying provider failed on Open. ---> System.Data.SqlClient.SqlException: A network-related or instance-specific error occurred while establishing a connection to SQL Server. The server was not found or was not accessible. Verify that the instance name is correct and that SQL Server is configured to allow remote connections. (provider: Named Pipes Provider, error: 40 - Could not open a connection to SQL Server) ---> System.ComponentModel.Win32Exception: The network path was not found
   --- End of inner exception stack trace ---
   at System.Data.SqlClient.SqlInternalConnectionTds..ctor(DbConnectionPoolIdentity identity, SqlConnectionString connectionOptions, SqlCredential credential, Object providerInfo, String newPassword, SecureString newSecurePassword, Boolean redirectedUserInstance, SqlConnectionString userConnectionOptions, SessionData reconnectSessionData, DbConnectionPool pool, String accessToken, Boolean applyTransientFaultHandling, SqlAuthenticationProviderManager sqlAuthProviderManager)
   at System.Data.SqlClient.SqlConnectionFactory.CreateConnection(DbConnectionOptions options, DbConnectionPoolKey poolKey, Object poolGroupProviderInfo, DbConnectionPool pool, DbConnection owningConnection, DbConnectionOptions userOptions)
   at System.Data.ProviderBase.DbConnectionFactory.CreatePooledConnection(DbConnectionPool pool, DbConnection owningObject, DbConnectionOptions options, DbConnectionPoolKey poolKey, DbConnectionOptions userOptions)
   at System.Data.ProviderBase.DbConnectionPool.CreateObject(DbConnection owningObject, DbConnectionOptions userOptions, DbConnectionInternal oldConnection)
   at System.Data.ProviderBase.DbConnectionPool.UserCreateRequest(DbConnection owningObject, DbConnectionOptions userOptions, DbConnectionInternal oldConnection)
   at System.Data.ProviderBase.DbConnectionPool.TryGetConnection(DbConnection owningObject, UInt32 waitForMultipleObjectsTimeout, Boolean allowCreate, Boolean onlyOneCheckConnection, DbConnectionOptions userOptions, DbConnectionInternal& connection)
   at System.Data.ProviderBase.DbConnectionPool.TryGetConnection(DbConnection owningObject, TaskCompletionSource`1 retry, DbConnectionOptions userOptions, DbConnectionInternal& connection)
   at System.Data.ProviderBase.DbConnectionFactory.TryGetConnection(DbConnection owningConnection, TaskCompletionSource`1 retry, DbConnectionOptions userOptions, DbConnectionInternal oldConnection, DbConnectionInternal& connection)
   at System.Data.ProviderBase.DbConnectionInternal.TryOpenConnectionInternal(DbConnection outerConnection, DbConnectionFactory connectionFactory, TaskCompletionSource`1 retry, DbConnectionOptions userOptions)
   at System.Data.ProviderBase.DbConnectionClosed.TryOpenConnection(DbConnection outerConnection, DbConnectionFactory connectionFactory, TaskCompletionSource`1 retry, DbConnectionOptions userOptions)
   at System.Data.SqlClient.SqlConnection.TryOpenInner(TaskCompletionSource`1 retry)
   at System.Data.SqlClient.SqlConnection.TryOpen(TaskCompletionSource`1 retry)
   at System.Data.SqlClient.SqlConnection.Open()
   at System.Data.Entity.Infrastructure.Interception.DbConnectionDispatcher.<Open>b__36(DbConnection t, DbConnectionInterceptionContext c)
   at System.Data.Entity.Infrastructure.Interception.InternalDispatcher`1.Dispatch[TTarget,TInterceptionContext](TTarget target, Action`2 operation, TInterceptionContext interceptionContext, Action`3 executing, Action`3 executed)
   at System.Data.Entity.Infrastructure.Interception.DbConnectionDispatcher.Open(DbConnection connection, DbInterceptionContext interceptionContext)
   at System.Data.Entity.Core.EntityClient.EntityConnection.<Open>b__2()
   at System.Data.Entity.SqlServer.DefaultSqlExecutionStrategy.<>c__DisplayClass1.<Execute>b__0()
   at System.Data.Entity.SqlServer.DefaultSqlExecutionStrategy.Execute[TResult](Func`1 operation)
   at System.Data.Entity.SqlServer.DefaultSqlExecutionStrategy.Execute(Action operation)
   at System.Data.Entity.Core.EntityClient.EntityConnection.Open()
   --- End of inner exception stack trace ---
   at System.Data.Entity.Core.EntityClient.EntityConnection.Open()
   at System.Data.Entity.Core.Objects.ObjectContext.EnsureConnection(Boolean shouldMonitorTransactions)
   at System.Data.Entity.Core.Objects.ObjectContext.ExecuteInTransaction[T](Func`1 func, IDbExecutionStrategy executionStrategy, Boolean startLocalTransaction, Boolean releaseConnectionOnSuccess)
   at System.Data.Entity.Core.Objects.ObjectQuery`1.<>c__DisplayClass7.<GetResults>b__5()
   at System.Data.Entity.SqlServer.DefaultSqlExecutionStrategy.Execute[TResult](Func`1 operation)
   at System.Data.Entity.Core.Objects.ObjectQuery`1.GetResults(Nullable`1 forMergeOption)
   at System.Data.Entity.Core.Objects.ObjectQuery`1.<System.Collections.Generic.IEnumerable<T>.GetEnumerator>b__0()
   at System.Data.Entity.Internal.LazyEnumerator`1.MoveNext()
   at System.Linq.Enumerable.FirstOrDefault[TSource](IEnumerable`1 source)
   at System.Data.Entity.Core.Objects.ELinq.ObjectQueryProvider.<GetElementFunction>b__1[TResult](IEnumerable`1 sequence)
   at System.Data.Entity.Core.Objects.ELinq.ObjectQueryProvider.ExecuteSingle[TResult](IEnumerable`1 query, Expression queryRoot)
   at System.Data.Entity.Core.Objects.ELinq.ObjectQueryProvider.System.Linq.IQueryProvider.Execute[TResult](Expression expression)
   at System.Data.Entity.Internal.Linq.DbQueryProvider.Execute[TResult](Expression expression)
   at System.Linq.Queryable.FirstOrDefault[TSource](IQueryable`1 source)
   at Ashirvad.Repo.Services.Area.User.User.<ValidateUser>d__1.MoveNext() in C:\Users\Uniqtech\Desktop\Ashirvad-main_2\Ashirvad\Ashirvad-main\Ashirvad.Repo\Services\Area\User\User.cs:line 55
--- End of stack trace from previous location where exception was thrown ---
   at System.Runtime.CompilerServices.TaskAwaiter.ThrowForNonSuccess(Task task)
   at System.Runtime.CompilerServices.TaskAwaiter.HandleNonSuccessAndDebuggerNotification(Task task)
   at System.Runtime.CompilerServices.TaskAwaiter`1.GetResult()
   at Ashirvad.ServiceAPI.Services.Area.User.UserService.<ValidateUser>d__3.MoveNext() in C:\Users\Uniqtech\Desktop\Ashirvad-main_2\Ashirvad\Ashirvad-main\Ashirvad.ServiceAPI\Services\Area\User\UserService.cs:line 46


2021-07-28 17:27:42,374 
Ashirvad.Logger.EventLogger                         [(null)] 
>> System.IO.DirectoryNotFoundException: Could not find a part of the path 'D:\Ashirvad\DOCS\TestPaper\'.
   at System.IO.__Error.WinIOError(Int32 errorCode, String maybeFullPath)
   at System.IO.FileStream.Init(String path, FileMode mode, FileAccess access, Int32 rights, Boolean useRights, FileShare share, Int32 bufferSize, FileOptions options, SECURITY_ATTRIBUTES secAttrs, String msgPath, Boolean bFromProxy, Boolean useLongPath, Boolean checkHost)
   at System.IO.FileStream..ctor(String path, FileMode mode, FileAccess access, FileShare share, Int32 bufferSize, FileOptions options, String msgPath, Boolean bFromProxy, Boolean useLongPath, Boolean checkHost)
   at System.IO.File.InternalWriteAllBytes(String path, Byte[] bytes, Boolean checkHost)
   at System.IO.File.WriteAllBytes(String path, Byte[] bytes)
   at Ashirvad.Common.Common.SaveFile(Byte[] content, String fileName, String path) in C:\Users\Uniqtech\Desktop\Ashirvad-main_2\Ashirvad\Ashirvad-main\Ashirvad.Common\Common.cs:line 54
   at Ashirvad.ServiceAPI.Services.Area.Test.TestService.<TestPaperMaintenance>d__7.MoveNext() in C:\Users\Uniqtech\Desktop\Ashirvad-main_2\Ashirvad\Ashirvad-main\Ashirvad.ServiceAPI\Services\Area\Test\TestService.cs:line 126


2021-07-28 17:44:05,173 
Ashirvad.Logger.EventLogger                         [(null)] 
>> System.IO.DirectoryNotFoundException: Could not find a part of the path 'D:\Ashirvad\DOCS\TestPaper\'.
   at System.IO.__Error.WinIOError(Int32 errorCode, String maybeFullPath)
   at System.IO.FileStream.Init(String path, FileMode mode, FileAccess access, Int32 rights, Boolean useRights, FileShare share, Int32 bufferSize, FileOptions options, SECURITY_ATTRIBUTES secAttrs, String msgPath, Boolean bFromProxy, Boolean useLongPath, Boolean checkHost)
   at System.IO.FileStream..ctor(String path, FileMode mode, FileAccess access, FileShare share, Int32 bufferSize, FileOptions options, String msgPath, Boolean bFromProxy, Boolean useLongPath, Boolean checkHost)
   at System.IO.File.InternalWriteAllBytes(String path, Byte[] bytes, Boolean checkHost)
   at System.IO.File.WriteAllBytes(String path, Byte[] bytes)
   at Ashirvad.Common.Common.SaveFile(Byte[] content, String fileName, String path) in C:\Users\Uniqtech\Desktop\Ashirvad-main_2\Ashirvad\Ashirvad-main\Ashirvad.Common\Common.cs:line 54
   at Ashirvad.ServiceAPI.Services.Area.Test.TestService.<TestPaperMaintenance>d__7.MoveNext() in C:\Users\Uniqtech\Desktop\Ashirvad-main_2\Ashirvad\Ashirvad-main\Ashirvad.ServiceAPI\Services\Area\Test\TestService.cs:line 126


2021-07-28 17:50:10,104 
Ashirvad.Logger.EventLogger                         [(null)] 
>> System.ArgumentNullException: Value cannot be null.
Parameter name: bytes
   at System.IO.File.WriteAllBytes(String path, Byte[] bytes)
   at Ashirvad.Common.Common.SaveFile(Byte[] content, String fileName, String path) in C:\Users\Uniqtech\Desktop\Ashirvad-main_2\Ashirvad\Ashirvad-main\Ashirvad.Common\Common.cs:line 54
   at Ashirvad.ServiceAPI.Services.Area.Test.TestService.<TestPaperMaintenance>d__7.MoveNext() in C:\Users\Uniqtech\Desktop\Ashirvad-main_2\Ashirvad\Ashirvad-main\Ashirvad.ServiceAPI\Services\Area\Test\TestService.cs:line 126


2021-07-28 17:51:23,694 
Ashirvad.Logger.EventLogger                         [(null)] 
>> System.ArgumentNullException: Value cannot be null.
Parameter name: bytes
   at System.IO.File.WriteAllBytes(String path, Byte[] bytes)
   at Ashirvad.Common.Common.SaveFile(Byte[] content, String fileName, String path) in C:\Users\Uniqtech\Desktop\Ashirvad-main_2\Ashirvad\Ashirvad-main\Ashirvad.Common\Common.cs:line 54
   at Ashirvad.ServiceAPI.Services.Area.Test.TestService.<TestPaperMaintenance>d__7.MoveNext() in C:\Users\Uniqtech\Desktop\Ashirvad-main_2\Ashirvad\Ashirvad-main\Ashirvad.ServiceAPI\Services\Area\Test\TestService.cs:line 126


2021-07-28 17:54:28,980 
Ashirvad.Logger.EventLogger                         [(null)] 
>> System.IO.DirectoryNotFoundException: Could not find a part of the path 'D:\Ashirvad\DOCS\TestPaper\'.
   at System.IO.__Error.WinIOError(Int32 errorCode, String maybeFullPath)
   at System.IO.FileStream.Init(String path, FileMode mode, FileAccess access, Int32 rights, Boolean useRights, FileShare share, Int32 bufferSize, FileOptions options, SECURITY_ATTRIBUTES secAttrs, String msgPath, Boolean bFromProxy, Boolean useLongPath, Boolean checkHost)
   at System.IO.FileStream..ctor(String path, FileMode mode, FileAccess access, FileShare share, Int32 bufferSize, FileOptions options, String msgPath, Boolean bFromProxy, Boolean useLongPath, Boolean checkHost)
   at System.IO.File.InternalWriteAllBytes(String path, Byte[] bytes, Boolean checkHost)
   at System.IO.File.WriteAllBytes(String path, Byte[] bytes)
   at Ashirvad.Common.Common.SaveFile(Byte[] content, String fileName, String path) in C:\Users\Uniqtech\Desktop\Ashirvad-main_2\Ashirvad\Ashirvad-main\Ashirvad.Common\Common.cs:line 54
   at Ashirvad.ServiceAPI.Services.Area.Test.TestService.<TestPaperMaintenance>d__7.MoveNext() in C:\Users\Uniqtech\Desktop\Ashirvad-main_2\Ashirvad\Ashirvad-main\Ashirvad.ServiceAPI\Services\Area\Test\TestService.cs:line 126


2021-07-28 17:55:30,150 
Ashirvad.Logger.EventLogger                         [(null)] 
>> System.Data.Entity.Validation.DbEntityValidationException: Validation failed for one or more entities. See 'EntityValidationErrors' property for more details.
   at System.Data.Entity.Internal.InternalContext.SaveChanges()
   at System.Data.Entity.Internal.LazyInternalContext.SaveChanges()
   at System.Data.Entity.DbContext.SaveChanges()
   at Ashirvad.Repo.Services.Area.ToDo.ToDo.<ToDoMaintenance>d__0.MoveNext() in C:\Users\Uniqtech\Desktop\Ashirvad-main_2\Ashirvad\Ashirvad-main\Ashirvad.Repo\Services\Area\ToDo\ToDo.cs:line 51
--- End of stack trace from previous location where exception was thrown ---
   at System.Runtime.CompilerServices.TaskAwaiter.ThrowForNonSuccess(Task task)
   at System.Runtime.CompilerServices.TaskAwaiter.HandleNonSuccessAndDebuggerNotification(Task task)
   at System.Runtime.CompilerServices.TaskAwaiter`1.GetResult()
   at Ashirvad.ServiceAPI.Services.Area.ToDo.ToDoService.<ToDoMaintenance>d__2.MoveNext() in C:\Users\Uniqtech\Desktop\Ashirvad-main_2\Ashirvad\Ashirvad-main\Ashirvad.ServiceAPI\Services\Area\ToDo\ToDoService.cs:line 38


2021-07-28 17:57:30,057 
Ashirvad.Logger.EventLogger                         [(null)] 
>> System.Data.Entity.Validation.DbEntityValidationException: Validation failed for one or more entities. See 'EntityValidationErrors' property for more details.
   at System.Data.Entity.Internal.InternalContext.SaveChanges()
   at System.Data.Entity.Internal.LazyInternalContext.SaveChanges()
   at System.Data.Entity.DbContext.SaveChanges()
   at Ashirvad.Repo.Services.Area.ToDo.ToDo.<ToDoMaintenance>d__0.MoveNext() in C:\Users\Uniqtech\Desktop\Ashirvad-main_2\Ashirvad\Ashirvad-main\Ashirvad.Repo\Services\Area\ToDo\ToDo.cs:line 51
--- End of stack trace from previous location where exception was thrown ---
   at System.Runtime.CompilerServices.TaskAwaiter.ThrowForNonSuccess(Task task)
   at System.Runtime.CompilerServices.TaskAwaiter.HandleNonSuccessAndDebuggerNotification(Task task)
   at System.Runtime.CompilerServices.TaskAwaiter`1.GetResult()
   at Ashirvad.ServiceAPI.Services.Area.ToDo.ToDoService.<ToDoMaintenance>d__2.MoveNext() in C:\Users\Uniqtech\Desktop\Ashirvad-main_2\Ashirvad\Ashirvad-main\Ashirvad.ServiceAPI\Services\Area\ToDo\ToDoService.cs:line 38


2021-07-28 18:01:41,138 
Ashirvad.Logger.EventLogger                         [(null)] 
>> System.Data.Entity.Validation.DbEntityValidationException: Validation failed for one or more entities. See 'EntityValidationErrors' property for more details.
   at System.Data.Entity.Internal.InternalContext.SaveChanges()
   at System.Data.Entity.Internal.LazyInternalContext.SaveChanges()
   at System.Data.Entity.DbContext.SaveChanges()
   at Ashirvad.Repo.ModelAccess.AddTransactionData(TransactionEntity transactionData) in C:\Users\Uniqtech\Desktop\Ashirvad-main_2\Ashirvad\Ashirvad-main\Ashirvad.Repo\ModelAccess.cs:line 53
   at Ashirvad.Repo.Services.Area.ToDo.ToDo.<ToDoMaintenance>d__0.MoveNext() in C:\Users\Uniqtech\Desktop\Ashirvad-main_2\Ashirvad\Ashirvad-main\Ashirvad.Repo\Services\Area\ToDo\ToDo.cs:line 33
--- End of stack trace from previous location where exception was thrown ---
   at System.Runtime.CompilerServices.TaskAwaiter.ThrowForNonSuccess(Task task)
   at System.Runtime.CompilerServices.TaskAwaiter.HandleNonSuccessAndDebuggerNotification(Task task)
   at System.Runtime.CompilerServices.TaskAwaiter`1.GetResult()
   at Ashirvad.ServiceAPI.Services.Area.ToDo.ToDoService.<ToDoMaintenance>d__2.MoveNext() in C:\Users\Uniqtech\Desktop\Ashirvad-main_2\Ashirvad\Ashirvad-main\Ashirvad.ServiceAPI\Services\Area\ToDo\ToDoService.cs:line 38


2021-07-28 18:04:16,094 
Ashirvad.Logger.EventLogger                         [(null)] 
>> System.Data.Entity.Validation.DbEntityValidationException: Validation failed for one or more entities. See 'EntityValidationErrors' property for more details.
   at System.Data.Entity.Internal.InternalContext.SaveChanges()
   at System.Data.Entity.Internal.LazyInternalContext.SaveChanges()
   at System.Data.Entity.DbContext.SaveChanges()
   at Ashirvad.Repo.Services.Area.ToDo.ToDo.<ToDoMaintenance>d__0.MoveNext() in C:\Users\Uniqtech\Desktop\Ashirvad-main_2\Ashirvad\Ashirvad-main\Ashirvad.Repo\Services\Area\ToDo\ToDo.cs:line 51
--- End of stack trace from previous location where exception was thrown ---
   at System.Runtime.CompilerServices.TaskAwaiter.ThrowForNonSuccess(Task task)
   at System.Runtime.CompilerServices.TaskAwaiter.HandleNonSuccessAndDebuggerNotification(Task task)
   at System.Runtime.CompilerServices.TaskAwaiter`1.GetResult()
   at Ashirvad.ServiceAPI.Services.Area.ToDo.ToDoService.<ToDoMaintenance>d__2.MoveNext() in C:\Users\Uniqtech\Desktop\Ashirvad-main_2\Ashirvad\Ashirvad-main\Ashirvad.ServiceAPI\Services\Area\ToDo\ToDoService.cs:line 38


2021-07-28 18:09:25,554 
Ashirvad.Logger.EventLogger                         [(null)] 
>> System.Data.Entity.Validation.DbEntityValidationException: Validation failed for one or more entities. See 'EntityValidationErrors' property for more details.
   at System.Data.Entity.Internal.InternalContext.SaveChanges()
   at System.Data.Entity.Internal.LazyInternalContext.SaveChanges()
   at System.Data.Entity.DbContext.SaveChanges()
   at Ashirvad.Repo.ModelAccess.AddTransactionData(TransactionEntity transactionData) in C:\Users\Uniqtech\Desktop\Ashirvad-main_2\Ashirvad\Ashirvad-main\Ashirvad.Repo\ModelAccess.cs:line 53
   at Ashirvad.Repo.Services.Area.ToDo.ToDo.<ToDoMaintenance>d__0.MoveNext() in C:\Users\Uniqtech\Desktop\Ashirvad-main_2\Ashirvad\Ashirvad-main\Ashirvad.Repo\Services\Area\ToDo\ToDo.cs:line 33
--- End of stack trace from previous location where exception was thrown ---
   at System.Runtime.CompilerServices.TaskAwaiter.ThrowForNonSuccess(Task task)
   at System.Runtime.CompilerServices.TaskAwaiter.HandleNonSuccessAndDebuggerNotification(Task task)
   at System.Runtime.CompilerServices.TaskAwaiter`1.GetResult()
   at Ashirvad.ServiceAPI.Services.Area.ToDo.ToDoService.<ToDoMaintenance>d__2.MoveNext() in C:\Users\Uniqtech\Desktop\Ashirvad-main_2\Ashirvad\Ashirvad-main\Ashirvad.ServiceAPI\Services\Area\ToDo\ToDoService.cs:line 38


2021-07-28 18:11:53,170 
Ashirvad.Logger.EventLogger                         [(null)] 
>> System.Data.Entity.Validation.DbEntityValidationException: Validation failed for one or more entities. See 'EntityValidationErrors' property for more details.
   at System.Data.Entity.Internal.InternalContext.SaveChanges()
   at System.Data.Entity.Internal.LazyInternalContext.SaveChanges()
   at System.Data.Entity.DbContext.SaveChanges()
   at Ashirvad.Repo.Services.Area.ToDo.ToDo.<ToDoMaintenance>d__0.MoveNext() in C:\Users\Uniqtech\Desktop\Ashirvad-main_2\Ashirvad\Ashirvad-main\Ashirvad.Repo\Services\Area\ToDo\ToDo.cs:line 51
--- End of stack trace from previous location where exception was thrown ---
   at System.Runtime.CompilerServices.TaskAwaiter.ThrowForNonSuccess(Task task)
   at System.Runtime.CompilerServices.TaskAwaiter.HandleNonSuccessAndDebuggerNotification(Task task)
   at System.Runtime.CompilerServices.TaskAwaiter`1.GetResult()
   at Ashirvad.ServiceAPI.Services.Area.ToDo.ToDoService.<ToDoMaintenance>d__2.MoveNext() in C:\Users\Uniqtech\Desktop\Ashirvad-main_2\Ashirvad\Ashirvad-main\Ashirvad.ServiceAPI\Services\Area\ToDo\ToDoService.cs:line 38


2021-07-28 18:14:33,296 
Ashirvad.Logger.EventLogger                         [(null)] 
>> System.Data.Entity.Validation.DbEntityValidationException: Validation failed for one or more entities. See 'EntityValidationErrors' property for more details.
   at System.Data.Entity.Internal.InternalContext.SaveChanges()
   at System.Data.Entity.Internal.LazyInternalContext.SaveChanges()
   at System.Data.Entity.DbContext.SaveChanges()
   at Ashirvad.Repo.Services.Area.ToDo.ToDo.<ToDoMaintenance>d__0.MoveNext() in C:\Users\Uniqtech\Desktop\Ashirvad-main_2\Ashirvad\Ashirvad-main\Ashirvad.Repo\Services\Area\ToDo\ToDo.cs:line 51
--- End of stack trace from previous location where exception was thrown ---
   at System.Runtime.CompilerServices.TaskAwaiter.ThrowForNonSuccess(Task task)
   at System.Runtime.CompilerServices.TaskAwaiter.HandleNonSuccessAndDebuggerNotification(Task task)
   at System.Runtime.CompilerServices.TaskAwaiter`1.GetResult()
   at Ashirvad.ServiceAPI.Services.Area.ToDo.ToDoService.<ToDoMaintenance>d__2.MoveNext() in C:\Users\Uniqtech\Desktop\Ashirvad-main_2\Ashirvad\Ashirvad-main\Ashirvad.ServiceAPI\Services\Area\ToDo\ToDoService.cs:line 38
